<?xml version="1.0"?>
<robot name="warehouse_robot">

  <material name="yellow">
    <color rgba="1 0.988 0.5 1"/>
  </material>
  <material name="black">
    <color rgba="0 0 0 1"/>
  </material>

  <link name="base_link">
    <visual>
      <origin xyz="0 0 0.5" rpy="0 0 0"/>
      <geometry><box size="1.0 1.0 1.0"/></geometry>
      <material name="yellow"/>
    </visual>
    <collision>
      <origin xyz="0 0 0.5" rpy="0 0 0"/>
      <geometry><box size="1.0 1.0 1.0"/></geometry>
    </collision>
    <inertial>
      <origin xyz="0 0 0.5" rpy="0 0 0"/>
      <mass value="5.0"/>
      <inertia ixx="0.1" ixy="0" ixz="0" iyy="0.1" iyz="0" izz="0.1"/>
    </inertial>
  </link>

  <link name="left_wheel">
    <visual>
      <geometry><cylinder radius="0.1" length="0.05"/></geometry>
      <material name="black"/>
    </visual>
    <collision>
      <geometry><cylinder radius="0.1" length="0.05"/></geometry>
    </collision>
    <inertial>
      <mass value="0.5"/>
      <inertia ixx="0.0005" ixy="0" ixz="0" iyy="0.0005" iyz="0" izz="0.001"/>
    </inertial>
  </link>

  <joint name="left_wheel_joint" type="continuous">
    <parent link="base_link"/>
    <child link="left_wheel"/>
    <origin xyz="0 0.55 0.1" rpy="-1.5708 0 0"/>
    <axis xyz="0 0 1"/>
  </joint>

  <link name="right_wheel">
    <visual>
      <geometry><cylinder radius="0.1" length="0.05"/></geometry>
      <material name="black"/>
    </visual>
    <collision>
      <geometry><cylinder radius="0.1" length="0.05"/></geometry>
    </collision>
    <inertial>
      <mass value="0.5"/>
      <inertia ixx="0.0005" ixy="0" ixz="0" iyy="0.0005" iyz="0" izz="0.001"/>
    </inertial>
  </link>

  <joint name="right_wheel_joint" type="continuous">
    <parent link="base_link"/>
    <child link="right_wheel"/>
    <origin xyz="0 -0.55 0.1" rpy="-1.5708 0 0"/>
    <axis xyz="0 0 1"/>
  </joint>

  <link name="caster_wheel">
    <visual>
      <geometry><sphere radius="0.05"/></geometry>
      <material name="black"/>
    </visual>
    <collision>
      <geometry><sphere radius="0.05"/></geometry> </collision>
    <inertial>
      <mass value="0.1"/>
      <inertia ixx="0.0001" ixy="0" ixz="0" iyy="0.0001" iyz="0" izz="0.0001"/>
    </inertial>
  </link>

  <joint name="caster_joint" type="fixed">
    <parent link="base_link"/>
    <child link="caster_wheel"/>
    <origin xyz="0.4 0 0.05" rpy="0 0 0"/>
  </joint>

  <gazebo reference="left_wheel">
    <mu1>100.0</mu1>  <!-- Friction coefficient -->
    <mu2>100.0</mu2>
    <kp>1000000.0</kp>  <!-- Contact stiffness -->
    <kd>100.0</kd>
  </gazebo>

  <gazebo reference="right_wheel">
    <mu1>100.0</mu1>
    <mu2>100.0</mu2>
    <kp>1000000.0</kp>
    <kd>100.0</kd>
  </gazebo>

  <gazebo>
  <plugin filename="gz-sim-diff-drive-system" name="gz::sim::systems::DiffDrive">
    <left_joint>left_wheel_joint</left_joint>
    <right_joint>right_wheel_joint</right_joint>
    <wheel_separation>1.1</wheel_separation>
    <wheel_radius>0.1</wheel_radius>
    <max_linear_velocity>2.0</max_linear_velocity>
    <min_linear_velocity>-2.0</min_linear_velocity>
    <max_angular_velocity>10.0</max_angular_velocity>
    <max_linear_acceleration>100.0</max_linear_acceleration>
    <max_angular_acceleration>100.0</max_angular_acceleration>
    
    <topic>/model/warehouse_robot/cmd_vel</topic>
    <odom_topic>/model/warehouse_robot/odometry</odom_topic>
    
    <frame_id>odom</frame_id>
    <child_frame_id>base_link</child_frame_id>
    <odom_publish_frequency>50</odom_publish_frequency>
    <initial_position>1.0 13.0 0.0</initial_position>
  </plugin>
  <plugin filename="gz-sim-joint-state-publisher-system" name="gz::sim::systems::JointStatePublisher"/>

  <plugin filename="gz-sim-pose-publisher-system" name="gz::sim::systems::PosePublisher">
    <publish_link_pose>true</publish_link_pose>
    <publish_sensor_pose>false</publish_sensor_pose>
    <publish_collision_pose>false</publish_collision_pose>
    <publish_visual_pose>false</publish_visual_pose>
    <publish_nested_model_pose>false</publish_nested_model_pose>
    <use_pose_vector_msg>true</use_pose_vector_msg>
    <static_publisher>false</static_publisher>
    <static_update_frequency>1</static_update_frequency>
  </plugin>
</gazebo>



</robot>